// async promisednumber(){
//     const promisenumber=()=>{ 
//         new Promise((resolve,reject)=>{
//         resolve(12)
//     })}
//     promisenumber.then((value)=>{
//         console.log(value)
//     }).catch((err)=>{
//        console.log(err)

// })

//assign uses try and the catch unlike the .then and catch in promises
// function promisednumber(){

//     let promise=NewPromise((resolve,reject))
// resolve(20)

// }

// const getPromised= async()=>{
//     try {
//         let resp = await promisednumber();
//        console.log(resp)
//     } catch (error) {
        
//     }
  
//}
